Workbook

Sheet README
A1: West Africa Mobility Corridor — Economics Model v1.0
A2: Mauritania landed cost · pilot P&L · driver-to-owner taxi · workshop and parts
A4: Prepared for | B4: Major Dream Williams
A5: Date | B5: 6 September 2026
A6: Phase | B6: Phase 0 — Supplier Discovery + Mauritania Evidence Sprint
A7: Status | B7: PLANNING MODEL. Not a price list, quotation, forecast, or investment memorandum.
A9: HOW TO USE THIS FILE
A10: 1 | B10: Edit ONLY the cells on the Assumptions tab. Every other tab is formulas.
A11: 2 | B11: BLUE text = an input you can change. BLACK text = a calculated cell — do not overwrite.
A12: 3 | B12: YELLOW fill = an unverified assumption that must be replaced with a sourced figure.
A13: 4 | B13: Each assumption carries an evidence label and a source in the columns beside it.
A15: EVIDENCE LABELS
A16: VERIFIED | B16: Supported by a named, reviewable source, cited in column E.
A17: CONFLICT | B17: Two credible sources disagree. Resolve before any external use.
A18: ASSUMPTION | B18: Planning placeholder. NOT evidence. Must be replaced before pricing.
A19: OPEN | B19: Unresolved, with a named owner in the dossier.
A21: HARD WARNING
B22: Roughly two thirds of the inputs in this model are ASSUMPTION or CONFLICT.
B23: No output of this model may be quoted to a buyer, published, used to take a deposit,
B24: or shown to an investor until the customs-broker opinion (O-01 to O-04 in the dossier)
B25: has replaced the tax and road-ready inputs with written, sourced figures.
A27: TABS
A28: Assumptions | B28: Every input, labelled and sourced. The only tab you edit.
A29: Landed Cost | B29: CIF to road-ready cost to indicative retail, by vehicle archetype.
A30: Pilot P&L | B30: Pilot economics at 10 and 25 units, including the 70% pre-sold gate.
A31: Taxi Driver-to-Owner | B31: Driver cash flow and the ownership ladder, benchmarked against Moove.
A32: Workshop & Parts | B32: Recurring service and parts economics — the durable revenue layer.
A33: Scenario | B33: Downside / base / upside on the variables that actually move the answer.

Sheet Assumptions
A1: ASSUMPTIONS — the only tab you edit
A2: Blue = input. Yellow fill = unverified. Column D = evidence label. Column E = source or owner.
A4: Input | B4: Value | C4: Unit | D4: Label | E4: Source / validation owner
A5: MAURITANIA TAX AND DUTY STACK
A6: Customs duty — top MFN band | B6: 0.2 | C6: % of CIF | D6: VERIFIED | E6: WTO TPR WT/TPR/S/371 (2018): bands 0/5/13/20; 20% on ~39% of lines, mainly final consumer goods
A7: Statistical fee | B7: 0.01 | C7: % of CIF | D7: CONFLICT | E7: Mauritania Trade Portal says 1%; Lloyds Bank Trade says 3%. RESOLVE — owner: Diallo + customs broker
A8: Culture/Sport tax (PCS) | B8: 0.01 | C8: % of CIF | D8: VERIFIED | E8: Mauritania Trade Portal — HS chapters 21-98, on CIF value
A9: Minimum flat-rate tax (IMF) | B9: 0.025 | C9: % of CIF | D9: CONFLICT | E9: Mauritania Trade Portal: 2.5% of CIF on imports; WTO TPR describes IMF at 2% in an export context. RESOLVE
A10: VAT | B10: 0.16 | C10: % of (CIF+duty) | D10: VERIFIED | E10: Mauritania Trade Portal; WTO TPR — standard rate 16%
A11: FREIGHT AND ROAD-READY COSTS
A12: Freight and marine insurance | B12: 0.09 | C12: % of FOB | D12: ASSUMPTION | E12: Planning placeholder. China-Nouakchott RoRo 34-46 days (Japanese Car Trade). OPEN O-04
A13: Port handling and THC, Nouakchott | B13: 450 | C13: USD/unit | D13: ASSUMPTION | E13: Planning placeholder. OPEN O-04 — owner: Diallo
A14: Customs broker fee | B14: 350 | C14: USD/unit | D14: ASSUMPTION | E14: Planning placeholder. OPEN O-04 — owner: Diallo
A15: Declaration processing fee | B15: 9 | C15: USD/decl. | D15: VERIFIED | E15: Mauritania Trade Portal — 3,000 old ouguiya, approx USD 8.60
A16: Inland transport to showroom | B16: 150 | C16: USD/unit | D16: ASSUMPTION | E16: Planning placeholder. OPEN O-04
A17: First registration and plates | B17: 300 | C17: USD/unit | D17: ASSUMPTION | E17: Planning placeholder. OPEN O-04
A18: Technical inspection | B18: 60 | C18: USD/unit | D18: ASSUMPTION | E18: Planning placeholder. OPEN O-04
A19: Motor insurance, year 1 | B19: 500 | C19: USD/unit | D19: ASSUMPTION | E19: Planning placeholder. Buyer may carry this. OPEN O-04
A20: PDI and first service | B20: 200 | C20: USD/unit | D20: ASSUMPTION | E20: Planning placeholder — owner: program team
A21: COMMERCIAL
A22: Target gross margin on road-ready cost | B22: 0.18 | C22: % | D22: ASSUMPTION | E22: Planning placeholder. Must be tested against the Nouakchott lot census (OPEN O-06)
A23: FX rate | B23: 40 | C23: MRU per USD | D23: ASSUMPTION | E23: Placeholder. Ouguiya depreciated only 0.13% y/y vs USD in 2025 (World Bank MPO)
A24: PILOT PARAMETERS
A25: Pilot size — option A | B25: 10 | C25: units | D25: PROPOSAL | E25: Sourcebook / strategy transcript: 10-25 unit pilot
A26: Pilot size — option B | B26: 25 | C26: units | D26: PROPOSAL | E26: Sourcebook / strategy transcript
A27: Pre-sold gate — minimum | B27: 0.7 | C27: % of pilot | D27: PROPOSAL | E27: HARD GATE. Do not proceed below this. Strategy transcript
A28: Demonstration units (not for sale) | B28: 2 | C28: units | D28: PROPOSAL | E28: Required to overcome brand unfamiliarity (Sagaci: ~30% unfamiliar with Chinese brands)
A29: Cost of capital | B29: 0.12 | C29: % per year | D29: ASSUMPTION | E29: Planning placeholder — owner: Major
A30: Days capital deployed per unit | B30: 120 | C30: days | D30: ASSUMPTION | E30: Order to cash. Includes 34-46 day RoRo transit (Japanese Car Trade)
A31: PILOT FIXED COSTS — one-off, not per unit
A32: Workshop setup and tooling | B32: 45000 | C32: USD | D32: ASSUMPTION | E32: Planning placeholder. OPEN — no quote obtained
A33: Diagnostic equipment and software licences | B33: 12000 | C33: USD | D33: ASSUMPTION | E33: Placeholder. Must come from supplier response (EOI item: diagnostics)
A34: Initial parts float | B34: 35000 | C34: USD | D34: ASSUMPTION | E34: Placeholder. Must come from supplier response (EOI item: spare-parts package)
A35: Technician training — cohort of 20 | B35: 30000 | C35: USD | D35: ASSUMPTION | E35: Placeholder. Train-the-trainer pathway, sourcebook
A36: Staff, 6 months | B36: 48000 | C36: USD | D36: ASSUMPTION | E36: Placeholder — owner: Diallo
A37: Premises, 6 months | B37: 24000 | C37: USD | D37: ASSUMPTION | E37: Placeholder — owner: Diallo
A38: Marketing, launch and portal | B38: 20000 | C38: USD | D38: ASSUMPTION | E38: Placeholder — owner: program team
A39: Legal, entity formation and compliance opinions | B39: 35000 | C39: USD | D39: ASSUMPTION | E39: Covers memo actions S-01 to S-07. Registration itself is 1-2 days via APIM (US ITA)
A40: TAXI DRIVER-TO-OWNER — all figures unverified for Nouakchott and Dakar
A41: Taxi vehicle road-ready cost | B41: 16000 | C41: USD | D41: ASSUMPTION | E41: Links to Landed Cost tab. Placeholder
...

Sheet Landed Cost
A1: LANDED COST — FOB to road-ready to indicative retail
A2: ALL FOB values are ASSUMPTION placeholders. Replace with actual supplier quotations before any use.
A4: Line item | B4: Rugged 4x4 SUV (new) | C4: Family SUV (new) | D4: Pickup / LCV (new) | E4: Hybrid SUV (new) | F4: EV demo (new) | G4: Certified used SUV | H4: Note
A5: FOB export price (supplier quotation) | B5: 21000 | C5: 15500 | D5: 17000 | E5: 23000 | F5: 26000 | G5: 9000 | H5: ASSUMPTION — placeholder. EOI/RFP asks each supplier for export price, currency, Incoterm and delivery point.
A6: Freight and marine insurance | B6: =B5*Assumptions!$B$12 -> 1890 | C6: =C5*Assumptions!$B$12 -> 1395 | D6: =D5*Assumptions!$B$12 -> 1530 | E6: =E5*Assumptions!$B$12 -> 2070 | F6: =F5*Assumptions!$B$12 -> 2340 | G6: =G5*Assumptions!$B$12 -> 810
A7: CIF value | B7: =B5+B6 -> 22890 | C7: =C5+C6 -> 16895 | D7: =D5+D6 -> 18530 | E7: =E5+E6 -> 25070 | F7: =F5+F6 -> 28340 | G7: =G5+G6 -> 9810
A8: Declared tax base | B8: =B7 -> 22890 | C8: =C7 -> 16895 | D8: =D7 -> 18530 | E8: =E7 -> 25070 | F8: =F7 -> 28340 | G8: =G7 -> 9810 | H8: USED VEHICLES: Mauritania applies a MINIMUM IMPORTATION VALUE, not invoice value (Lloyds Bank Trade; US ITA reports Argus-based minimums). For the used column this cell must be REPLACED with the administrative minimum value once obtained — OPEN O-01.
A9: Customs duty | B9: =B8*Assumptions!$B$6 -> 4578 | C9: =C8*Assumptions!$B$6 -> 3379 | D9: =D8*Assumptions!$B$6 -> 3706 | E9: =E8*Assumptions!$B$6 -> 5014 | F9: =F8*Assumptions!$B$6 -> 5668 | G9: =G8*Assumptions!$B$6 -> 1962
A10: Statistical fee | B10: =B8*Assumptions!$B$7 -> 228.9 | C10: =C8*Assumptions!$B$7 -> 168.95 | D10: =D8*Assumptions!$B$7 -> 185.3 | E10: =E8*Assumptions!$B$7 -> 250.7 | F10: =F8*Assumptions!$B$7 -> 283.4 | G10: =G8*Assumptions!$B$7 -> 98.1 | H10: CONFLICT 1% vs 3%
A11: Culture/Sport tax (PCS) | B11: =B8*Assumptions!$B$8 -> 228.9 | C11: =C8*Assumptions!$B$8 -> 168.95 | D11: =D8*Assumptions!$B$8 -> 185.3 | E11: =E8*Assumptions!$B$8 -> 250.7 | F11: =F8*Assumptions!$B$8 -> 283.4 | G11: =G8*Assumptions!$B$8 -> 98.1
A12: Minimum flat-rate tax (IMF) | B12: =B8*Assumptions!$B$9 -> 572.25 | C12: =C8*Assumptions!$B$9 -> 422.375 | D12: =D8*Assumptions!$B$9 -> 463.25 | E12: =E8*Assumptions!$B$9 -> 626.75 | F12: =F8*Assumptions!$B$9 -> 708.5 | G12: =G8*Assumptions!$B$9 -> 245.25 | H12: CONFLICT 2.5% import vs 2% export
A13: VAT | B13: =(B8+B9)*Assumptions!$B$10 -> 4394.88 | C13: =(C8+C9)*Assumptions!$B$10 -> 3243.84 | D13: =(D8+D9)*Assumptions!$B$10 -> 3557.76 | E13: =(E8+E9)*Assumptions!$B$10 -> 4813.44 | F13: =(F8+F9)*Assumptions!$B$10 -> 5441.28 | G13: =(G8+G9)*Assumptions!$B$10 -> 1883.52 | H13: VAT charged on CIF + duty
A14: Total duties and taxes | B14: =SUM(B9:B13) -> 10002.93 | C14: =SUM(C9:C13) -> 7383.115 | D14: =SUM(D9:D13) -> 8097.61 | E14: =SUM(E9:E13) -> 10955.59 | F14: =SUM(F9:F13) -> 12384.58 | G14: =SUM(G9:G13) -> 4286.97
A15: Effective tax uplift on CIF | B15: =IFERROR(B14/B7,0) -> 0.437 | C15: =IFERROR(C14/C7,0) -> 0.437 | D15: =IFERROR(D14/D7,0) -> 0.437 | E15: =IFERROR(E14/E7,0) -> 0.437 | F15: =IFERROR(F14/F7,0) -> 0.437 | G15: =IFERROR(G14/G7,0) -> 0.437
A17: Port handling and THC | B17: =Assumptions!$B$13 -> 450 | C17: =Assumptions!$B$13 -> 450 | D17: =Assumptions!$B$13 -> 450 | E17: =Assumptions!$B$13 -> 450 | F17: =Assumptions!$B$13 -> 450 | G17: =Assumptions!$B$13 -> 450
A18: Customs broker | B18: =Assumptions!$B$14 -> 350 | C18: =Assumptions!$B$14 -> 350 | D18: =Assumptions!$B$14 -> 350 | E18: =Assumptions!$B$14 -> 350 | F18: =Assumptions!$B$14 -> 350 | G18: =Assumptions!$B$14 -> 350
A19: Declaration fee | B19: =Assumptions!$B$15 -> 9 | C19: =Assumptions!$B$15 -> 9 | D19: =Assumptions!$B$15 -> 9 | E19: =Assumptions!$B$15 -> 9 | F19: =Assumptions!$B$15 -> 9 | G19: =Assumptions!$B$15 -> 9
A20: Inland transport | B20: =Assumptions!$B$16 -> 150 | C20: =Assumptions!$B$16 -> 150 | D20: =Assumptions!$B$16 -> 150 | E20: =Assumptions!$B$16 -> 150 | F20: =Assumptions!$B$16 -> 150 | G20: =Assumptions!$B$16 -> 150
A21: Registration and plates | B21: =Assumptions!$B$17 -> 300 | C21: =Assumptions!$B$17 -> 300 | D21: =Assumptions!$B$17 -> 300 | E21: =Assumptions!$B$17 -> 300 | F21: =Assumptions!$B$17 -> 300 | G21: =Assumptions!$B$17 -> 300
A22: Technical inspection | B22: =Assumptions!$B$18 -> 60 | C22: =Assumptions!$B$18 -> 60 | D22: =Assumptions!$B$18 -> 60 | E22: =Assumptions!$B$18 -> 60 | F22: =Assumptions!$B$18 -> 60 | G22: =Assumptions!$B$18 -> 60
A23: PDI and first service | B23: =Assumptions!$B$20 -> 200 | C23: =Assumptions!$B$20 -> 200 | D23: =Assumptions!$B$20 -> 200 | E23: =Assumptions!$B$20 -> 200 | F23: =Assumptions!$B$20 -> 200 | G23: =Assumptions!$B$20 -> 200
A24: Total road-ready costs | B24: =SUM(B17:B23) -> 1519 | C24: =SUM(C17:C23) -> 1519 | D24: =SUM(D17:D23) -> 1519 | E24: =SUM(E17:E23) -> 1519 | F24: =SUM(F17:F23) -> 1519 | G24: =SUM(G17:G23) -> 1519
A26: TOTAL ROAD-READY COST | B26: =B7+B14+B24 -> 34411.93 | C26: =C7+C14+C24 -> 25797.115 | D26: =D7+D14+D24 -> 28146.61 | E26: =E7+E14+E24 -> 37544.59 | F26: =F7+F14+F24 -> 42243.58 | G26: =G7+G14+G24 -> 15615.97
A27: Total uplift over FOB | B27: =IFERROR(B26/B5-1,0) -> 0.63866333 | C27: =IFERROR(C26/C5-1,0) -> 0.66433 | D27: =IFERROR(D26/D5-1,0) -> 0.65568294 | E27: =IFERROR(E26/E5-1,0) -> 0.63237348 | F27: =IFERROR(F26/F5-1,0) -> 0.62475308 | G27: =IFERROR(G26/G5-1,0) -> 0.73510778
A28: Financing cost while in transit | B28: =B26*Assumptions!$B$29*Assumptions!$B$30/365 -> 1357.6213 | C28: =C26*Assumptions!$B$29*Assumptions!$B$30/365 -> 1017.7492 | D28: =D26*Assumptions!$B$29*Assumptions!$B$30/365 -> 1110.4416 | E28: =E26*Assumptions!$B$29*Assumptions!$B$30/365 -> 1481.2112 | F28: =F26*Assumptions!$B$29*Assumptions!$B$30/365 -> 1666.596 | G28: =G26*Assumptions!$B$29*Assumptions!$B$30/365 -> 616.0821 | H28: Capital tied up from order to cash. This is the line the Moove precedent shows people underestimate.
A29: Fully loaded unit cost | B29: =B26+B28 -> 35769.551 | C29: =C26+C28 -> 26814.864 | D29: =D26+D28 -> 29257.052 | E29: =E26+E28 -> 39025.801 | F29: =F26+F28 -> 43910.176 | G29: =G26+G28 -> 16232.052
A30: Gross margin at target | B30: =B29*Assumptions!$B$22 -> 6438.5192 | C30: =C29*Assumptions!$B$22 -> 4826.6756 | D30: =D29*Assumptions!$B$22 -> 5266.2693 | E30: =E29*Assumptions!$B$22 -> 7024.6442 | F30: =F29*Assumptions!$B$22 -> 7903.8317 | G30: =G29*Assumptions!$B$22 -> 2921.7694
A31: INDICATIVE RETAIL (USD) | B31: =B29+B30 -> 42208.071 | C31: =C29+C30 -> 31641.54 | D31: =D29+D30 -> 34523.321 | E31: =E29+E30 -> 46050.445 | F31: =F29+F30 -> 51814.008 | G31: =G29+G30 -> 19153.821
A32: INDICATIVE RETAIL (MRU) | B32: =B31*Assumptions!$B$23 -> 1688322.8 | C32: =C31*Assumptions!$B$23 -> 1265661.6 | D32: =D31*Assumptions!$B$23 -> 1380932.8 | E32: =E31*Assumptions!$B$23 -> 1842017.8 | F32: =F31*Assumptions!$B$23 -> 2072560.3 | G32: =G31*Assumptions!$B$23 -> 766152.86
A33: Motor insurance year 1 (buyer-borne) | B33: =Assumptions!$B$19 -> 500 | C33: =Assumptions!$B$19 -> 500 | D33: =Assumptions!$B$19 -> 500 | E33: =Assumptions!$B$19 -> 500 | F33: =Assumptions!$B$19 -> 500 | G33: =Assumptions!$B$19 -> 500 | H33: Shown separately — normally borne by the buyer, not the importer.
A35: DO NOT QUOTE ANY FIGURE ON THIS TAB TO A BUYER.
A36: Every tax and road-ready input is ASSUMPTION or CONFLICT until the customs-broker opinion (dossier O-01 to O-04) is on file.

Sheet Pilot P&L
A1: PILOT P&L — 10 unit and 25 unit scenarios
A2: Assumes the Rugged 4x4 SUV archetype. Change the linked column on Landed Cost to model a different mix.
A4: Line | B4: Option A | C4: Option B | D4: Note
A5: Units in pilot | B5: =Assumptions!$B$25 -> 10 | C5: =Assumptions!$B$26 -> 25
A6: Demonstration units (not sold) | B6: =Assumptions!$B$28 -> 2 | C6: =Assumptions!$B$28 -> 2 | D6: Held back to address brand unfamiliarity. Sagaci: ~30% of African respondents unfamiliar with Chinese brands.
A7: Units available for sale | B7: =B5-B6 -> 8 | C7: =C5-C6 -> 23
A8: Pre-sold gate (minimum) | B8: =Assumptions!$B$27 -> 0.7 | C8: =Assumptions!$B$27 -> 0.7
A9: Units that must be pre-sold before proceeding | B9: =ROUNDUP(B7*B8,0) -> 6 | C9: =ROUNDUP(C7*C8,0) -> 17 | D9: HARD GATE. Below this, do not place the order. The discipline to walk away is what protects the capital.
A11: Fully loaded cost per unit | B11: ='Landed Cost'!B29 -> 35769.551 | C11: ='Landed Cost'!B29 -> 35769.551
A12: Indicative retail per unit | B12: ='Landed Cost'!B31 -> 42208.071 | C12: ='Landed Cost'!B31 -> 42208.071
A13: Gross margin per unit | B13: =B12-B11 -> 6438.5192 | C13: =C12-C11 -> 6438.5192
A15: Vehicle capital required | B15: =B5*B11 -> 357695.51 | C15: =C5*C11 -> 894238.78
A16: Workshop setup and tooling | B16: =Assumptions!$B$32 -> 45000 | C16: =Assumptions!$B$32 -> 45000
A17: Diagnostic equipment and software | B17: =Assumptions!$B$33 -> 12000 | C17: =Assumptions!$B$33 -> 12000
A18: Initial parts float | B18: =Assumptions!$B$34 -> 35000 | C18: =Assumptions!$B$34 -> 35000
A19: Technician training (cohort of 20) | B19: =Assumptions!$B$35 -> 30000 | C19: =Assumptions!$B$35 -> 30000
A20: Staff, 6 months | B20: =Assumptions!$B$36 -> 48000 | C20: =Assumptions!$B$36 -> 48000
A21: Premises, 6 months | B21: =Assumptions!$B$37 -> 24000 | C21: =Assumptions!$B$37 -> 24000
A22: Marketing, launch and portal | B22: =Assumptions!$B$38 -> 20000 | C22: =Assumptions!$B$38 -> 20000
A23: Legal, entity and compliance opinions | B23: =Assumptions!$B$39 -> 35000 | C23: =Assumptions!$B$39 -> 35000
A24: Total infrastructure and setup | B24: =SUM(B16:B23) -> 249000 | C24: =SUM(C16:C23) -> 249000 | D24: This is the number that separates a mobility business from a vehicle trade. It does not scale with unit count.
A25: TOTAL CAPITAL REQUIRED | B25: =B15+B24 -> 606695.51 | C25: =C15+C24 -> 1143238.8
A27: Vehicle sales revenue (units sold) | B27: =B7*B12 -> 337664.56 | C27: =C7*C12 -> 970785.62
A28: Vehicle cost of sales | B28: =B7*B11 -> 286156.41 | C28: =C7*C11 -> 822699.68
A29: Gross profit on vehicles | B29: =B27-B28 -> 51508.154 | C29: =C27-C28 -> 148085.94
A30: Service and parts gross profit, year 1 | B30: =B7*'Workshop & Parts'!$B$12 -> 2324.4 | C30: =C7*'Workshop & Parts'!$B$12 -> 6682.65 | D30: The recurring layer. This is the razor-blade revenue that makes the vehicle sale worth making.
A31: Total gross profit | B31: =B29+B30 -> 53832.554 | C31: =C29+C30 -> 154768.59
A32: Setup cost carried in period | B32: =B24 -> 249000 | C32: =C24 -> 249000
A33: PILOT RESULT BEFORE TAX | B33: =B31-B32 -> -195167.45 | C33: =C31-C32 -> -94231.407
A34: Return on total capital | B34: =IFERROR(B33/B25,0) -> -0.32168929 | C34: =IFERROR(C33/C25,0) -> -0.082424957
A36: Demo unit cost written into marketing | B36: =B6*B11 -> 71539.103 | C36: =C6*C11 -> 71539.103
A37: Break-even units sold (covers setup) | B37: =IFERROR(ROUNDUP(B24/B13,0),0) -> 39 | C37: =IFERROR(ROUNDUP(C24/C13,0),0) -> 39 | D37: Units needed on vehicle margin alone to cover setup. If this exceeds units available for sale, the pilot cannot pay for its own infrastructure — which is expected, and is why the service layer matters.
A39: READ THIS BEFORE USING THE RESULT
A40: A negative pilot result is not a failure of the thesis. Setup cost is a one-off that builds the service capability;
A41: the returns appear in years 2-3 through parts, service, fleet and repeat sales. The question this tab answers is
A42: "how much capital is at risk, and for how long" — not "is this profitable in period one".

Sheet Taxi Driver-to-Owner
A1: DRIVER-TO-OWNER TAXI LADDER
A2: Designed against the Moove precedent, not modelled on it. Every driver figure is UNVERIFIED — dossier O-13.
A4: Line | B4: Value | C4: Note
A5: DRIVER MONTHLY CASH FLOW
A6: Gross revenue per day | B6: =Assumptions!$B$42 -> 28 | C6: UNVERIFIED — 10 driver interviews per city required
A7: Working days per month | B7: =Assumptions!$B$43 -> 26
A8: Gross monthly revenue | B8: =B6*B7 -> 728
A9: Fuel | B9: =-Assumptions!$B$44*B7 -> -234
A10: Insurance and licence | B10: =-Assumptions!$B$46 -> -70
A11: Maintenance and tyres | B11: =-Assumptions!$B$45 -> -90 | C11: CARRIED BY THE FLEET SPV, not the driver — shown here to size the true cost of the asset. See architecture memo.
A12: Driver net before ladder payment | B12: =B8+B9+B10 -> 424 | C12: Excludes maintenance, because the SPV carries it. This is the number the payment must be sized against.
A14: LADDER PAYMENT
A15: Vehicle road-ready cost | B15: =Assumptions!$B$41 -> 16000
A16: Disclosed financing markup | B16: =Assumptions!$B$48 -> 0.3 | C16: Murabaha-style. Source from a LICENSED institution, do not replicate in-house.
A17: Total amount payable | B17: =B15*(1+B16) -> 20800
A18: Term | B18: =Assumptions!$B$47 -> 36
A19: Scheduled monthly payment | B19: =IFERROR(B17/B18,0) -> 577.77778
A20: Payment as % of driver net | B20: =IFERROR(B19/B12,0) -> 1.3626834
A21: Ceiling on payment as % of net | B21: =Assumptions!$B$50 -> 0.45 | C21: HARD CEILING — anti-extraction safeguard
A22: Maximum affordable payment | B22: =B12*B21 -> 190.8
A23: GATE: is the schedule affordable? | B23: =IF(B19<=B22,"PASS","FAIL - restructure or do not launch") -> FAIL - restructure or do not launch | C23: If FAIL: lengthen the term, lower the markup, or choose a cheaper vehicle. Do NOT push the gap onto the driver.
A24: Driver income after payment | B24: =B12-B19 -> -153.77778
A25: Implied term at the affordability ceiling | B25: =IFERROR(ROUNDUP(B17/B22,0),0) -> 110 | C25: Months required if the payment is capped at the affordability ceiling. Compare against the term above.
A27: SPV VIEW
A28: Annual payments received per vehicle | B28: =B19*12 -> 6933.3333
A29: Annual maintenance carried by SPV | B29: =-Assumptions!$B$45*12 -> -1080
A30: Net annual cash per vehicle | B30: =B28+B29 -> 5853.3333
A31: Simple payback on vehicle cost (years) | B31: =IFERROR(B15/B30,0) -> 2.7334852
A32: Cure period before repossession | B32: =Assumptions!$B$49 -> 60 | C32: Moove repossessed vehicles from drivers who missed KPIs (Techpoint Africa). A documented cure period is the difference between a ladder and a trap.
A34: ANTI-EXTRACTION RULES BUILT INTO THIS SHEET
A35: 1. Payment is sized against evidenced driver net earnings, not against the financier recovery schedule.
A36: 2. Maintenance is carried by the SPV. A driver who cannot afford a repair must not lose the asset over it.
A37: 3. A documented cure period precedes any repossession.
A38: 4. Accrued equity is retained on partial performance, never reset to zero.
A39: 5. No rung of the ladder requires the driver to take personal recourse debt.
A40: If these rules make the vertical uneconomic, that is a finding — not a reason to remove the rules.

Sheet Workshop & Parts
A1: WORKSHOP AND PARTS — the recurring layer
A2: Senegal parts market context: USD 38.6m imports in 2024, China largest source at 18%, >2,000 importers, no firm above 10% share.
A4: Line | B4: Value | C4: Note
A5: PER VEHICLE PER YEAR
A6: Service visits per year | B6: =Assumptions!$B$52 -> 3
A7: Labour revenue per visit | B7: =Assumptions!$B$53 -> 85
A8: Parts revenue per visit | B8: =Assumptions!$B$54 -> 130
A9: Annual revenue per vehicle | B9: =B6*(B7+B8) -> 645
A10: Labour gross profit | B10: =B6*B7*Assumptions!$B$56 -> 165.75
A11: Parts gross profit | B11: =B6*B8*Assumptions!$B$55 -> 124.8
A12: ANNUAL GROSS PROFIT PER VEHICLE | B12: =B10+B11 -> 290.55 | C12: This cell feeds the Pilot P&L. It is the whole argument for building service capability before selling volume.
A14: AT SCALE
A15: Serviceable vehicles by end of year 2 | B15: =Assumptions!$B$57 -> 120 | C15: Includes non-corridor vehicles — a workshop that only serves its own brand is under-utilised.
A16: Annual service and parts revenue | B16: =B15*B9 -> 77400
A17: Annual service and parts gross profit | B17: =B15*B12 -> 34866
A18: Vehicle-sale gross profit equivalent | B18: =IFERROR(B17/'Landed Cost'!B30,0) -> 5.4152203 | C18: How many vehicle sales the service layer is worth per year. When this exceeds realistic sales volume, the service business IS the business.
A20: WHY THIS TAB MATTERS MORE THAN THE PILOT P&L
A21: Mauritania removed its vehicle import age limit in 2017, so a new Chinese SUV competes against unrestricted aged imports.
A22: Senegal raised its limits to 10 and 15 years by decree on 24 October 2025, and ~80% of its registered fleet is already 10+ years old.
A23: Neither market is short of vehicles. Both are short of trustworthy service, documented history, and parts availability.
A24: That is the gap the corridor can actually own, and no OEM authorization is required to enter it.

Sheet Scenario
A1: SCENARIO — the variables that actually move the answer
A2: Downside / Base / Upside. Base column links live to Assumptions; downside and upside are stress inputs.
A4: Variable | B4: Downside | C4: Base | D4: Upside | E4: Why it matters
A5: Effective tax uplift on CIF | B5: 0.6 | C5: ='Landed Cost'!B15 -> 0.437 | D5: 0.38 | E5: The CONFLICT items (statistical fee, IMF) and any vehicle-specific levy sit here. Widest single uncertainty.
A6: Freight as % of FOB | B6: 0.14 | C6: =Assumptions!$B$12 -> 0.09 | D6: 0.06 | E6: RoRo China-Nouakchott is 34-46 days; rates are volatile.
A7: Target gross margin | B7: 0.1 | C7: =Assumptions!$B$22 -> 0.18 | D7: 0.24 | E7: Constrained by aged-import competition, not by cost.
A8: Pre-sold share achieved | B8: 0.4 | C8: =Assumptions!$B$27 -> 0.7 | D8: 0.9 | E8: Below the 70% gate the pilot does not launch.
A9: Days capital deployed | B9: 210 | C9: =Assumptions!$B$30 -> 120 | D9: 75 | E9: Port delays and inconsistent clearance are documented risks.
A10: Service visits per vehicle per year | B10: 1.5 | C10: =Assumptions!$B$52 -> 3 | D10: 4.5 | E10: Drives the entire recurring layer.
A11: Driver gross daily revenue (USD) | B11: 18 | C11: =Assumptions!$B$42 -> 28 | D11: 40 | E11: Wholly unverified. Determines whether the taxi vertical exists at all.
A14: DOWNSIDE UNIT ECONOMICS CHECK
A15: Road-ready cost at downside tax uplift | B15: ='Landed Cost'!B7*(1+B5)+'Landed Cost'!B24 -> 38143
A16: Retail at downside cost and downside margin | B16: =B15*(1+B7) -> 41957.3
A17: Base retail for comparison | B17: ='Landed Cost'!B31 -> 42208.071
A18: Downside vs base retail | B18: =IFERROR(B16/B17-1,0) -> -0.0059412948 | E18: If the downside retail price exceeds what the lot census says buyers pay, the pilot has no price headroom.
A19: Downside gross profit per unit | B19: =B16-B15 -> 3814.3 | E19: The real downside bite: higher tax uplift AND compressed margin. Compare with the base figure below.
A20: Base gross profit per unit | B20: ='Landed Cost'!B30 -> 6438.5192
A21: Downside vs base gross profit | B21: =IFERROR(B19/B20-1,0) -> -0.40758118
A22: 2. That buyers will pay a premium over aged imports for an unfamiliar brand. Untested — needs the 25 interviews and the lot census.
A23: THE THREE ASSUMPTIONS MOST LIKELY TO BREAK THIS
A24: 1. That the tax stack is what desk research says it is. It is built on two unresolved CONFLICTs and a 2017 decree in a redenominated currency.
A25: 2. That buyers will pay a premium over aged imports for an unfamiliar brand. Untested — needs the 25 interviews and the lot census.
A26: 3. That service revenue materialises at the assumed frequency and margin. No workshop registry exists in either country yet.
